<robot name="quadruped">  
  <material name="blue">
    <color rgba="0 0 0.8 1"/>
  </material>
  <material name="black">
    <color rgba="0 0 0 1"/>  
  </material>
  <material name="white">
    <color rgba="1 1 1 1"/>
  </material>
  <material name="red"> 
    <color rgba="1 0 0 1"/> 
  </material> 

  <link name="main_body"> 
  	<visual>
      <origin xyz="0 0 0.75"/>
      <geometry>
        <box size="1.5 0.8 0.3"/>
      </geometry>
      <material name="red"/>
    </visual>
    <collision>
      <geometry>
        <box size="1.5 0.8 0.3"/>
      </geometry>
    </collision>
    <inertial>
      <mass value="7.5"/> 
      <inertia ixx="1.0" ixy="0.0" ixz="0.0" iyy="1.0" iyz="0.0" izz="1.0"/>
    </inertial>
  </link>

  <link name="upper1">
  	<visual>
      <origin xyz="-0.212 0 -0.2" rpy="0 0.785 0"/>
      <geometry>
        <cylinder length="0.6" radius="0.1"/>
      </geometry>
      <material name="white"/>
    </visual>
    <collision>
      <geometry>
        <cylinder length="0.6" radius="0.1"/>
      </geometry>
    </collision>
    <inertial>
      <mass value="0.5"/>
      <inertia ixx="1.0" ixy="0.0" ixz="0.0" iyy="1.0" iyz="0.0" izz="1.0"/>
    </inertial>
  </link>

  <link name="lower1">
  	<visual>
      <origin xyz="0.1475 0 -0.15" rpy="0 -0.785 0"/>
      <geometry>
        <cylinder length="0.6" radius="0.1"/>
      </geometry>
      <material name="blue"/>
    </visual>
    <collision>
      <geometry>
        <cylinder length="0.6" radius="0.1"/>
      </geometry>
    </collision>
    <inertial>
      <mass value="0.5"/>
      <inertia ixx="1.0" ixy="0.0" ixz="0.0" iyy="1.0" iyz="0.0" izz="1.0"/>
    </inertial>
  </link>
 
  <joint name="front_left_upper" type="revolute">
    <parent link="main_body"/>
      <child link="upper1"/>
    <axis xyz="0 1 0"/>
    <origin xyz="0.6 0.25 0.6" rpy="0 0 0"/>
    <limit effort="100" lower="-1.6" upper="0.3" velocity="0.5"/>
  </joint>
  
  <joint name="front_left_lower" type="revolute">
    <parent link="upper1"/> 
    <child link="lower1"/>
    <axis xyz="0 1 0"/>
    <origin xyz="-0.42 0 -0.42" rpy="0 0 0"/>
    <limit effort="100" lower="-0.4" upper="1.58" velocity="0.5"/>
  </joint>

  <link name="upper2">
  	<visual>
      <origin xyz="-0.212 0 -0.2" rpy="0 0.785 0"/>
      <geometry>
        <cylinder length="0.6" radius="0.1"/>
      </geometry>
      <material name="white"/>
    </visual>
    <collision>
      <geometry>
        <cylinder length="0.6" radius="0.1"/>
      </geometry>
    </collision>
    <inertial>
      <mass value="0.5"/>
      <inertia ixx="1.0" ixy="0.0" ixz="0.0" iyy="1.0" iyz="0.0" izz="1.0"/>
    </inertial>
  </link>

  <link name="lower2">
  	<visual>
      <origin xyz="0.1475 0 -0.15" rpy="0 -0.785 0"/>
      <geometry>
        <cylinder length="0.6" radius="0.1"/>
      </geometry>
      <material name="blue"/>
    </visual>
    <collision>
      <geometry>
        <cylinder length="0.6" radius="0.1"/>
      </geometry>
    </collision>
    <inertial>
      <mass value="0.5"/>
      <inertia ixx="1.0" ixy="0.0" ixz="0.0" iyy="1.0" iyz="0.0" izz="1.0"/>
    </inertial>
  </link>

  <joint name="back_left_upper" type="revolute">
    <parent link="main_body"/>
    <child link="upper2"/>
    <axis xyz="0 1 0"/>
    <origin xyz="-0.27 0.25 0.6" rpy="0 0 0"/>
    <limit effort="100" lower="-1.6" upper="0.3" velocity="0.5"/>
  </joint>

  <joint name="back_left_lower" type="revolute">
    <parent link="upper2"/>
    <child link="lower2"/>
    <axis xyz="0 1 0"/>
    <origin xyz="-0.42 0 -0.42" rpy="0 0 0"/>
    <limit effort="100" lower="-0.4" upper="1.58" velocity="0.5"/>
  </joint>
 
  <link name="upper3">
  	<visual>
      <origin xyz="-0.212 0 -0.2" rpy="0 0.785 0"/>
      <geometry>
        <cylinder length="0.6" radius="0.1"/>
      </geometry>
      <material name="white"/>
    </visual>
    <collision>
      <geometry>
        <cylinder length="0.6" radius="0.1"/>
      </geometry>
    </collision>
    <inertial>
      <mass value="0.5"/>
      <inertia ixx="1.0" ixy="0.0" ixz="0.0" iyy="1.0" iyz="0.0" izz="1.0"/>
    </inertial>
  </link>

  <link name="lower3">
  	<visual>
      <origin xyz="0.1475 0 -0.15" rpy="0 -0.785 0"/>
      <geometry>
        <cylinder length="0.6" radius="0.1"/>
      </geometry>
      <material name="blue"/>
    </visual>
    <collision>
      <geometry>
        <cylinder length="0.6" radius="0.1"/>
      </geometry>
    </collision>
    <inertial>
      <mass value="0.5"/>
      <inertia ixx="1.0" ixy="0.0" ixz="0.0" iyy="1.0" iyz="0.0" izz="1.0"/>
    </inertial>
  </link>

  <joint name="front_right_upper" type="revolute">
    <parent link="main_body"/>
    <child link="upper3"/>
    <axis xyz="0 1 0"/>
    <origin xyz="0.6 -0.25 0.6" rpy="0 0 0"/>
    <limit effort="100" lower="-1.6" upper="0.3" velocity="0.5"/>
  </joint>

  <joint name="front_right_lower" type="revolute">
    <parent link="upper3"/>
    <child link="lower3"/>
    <axis xyz="0 1 0"/>
    <origin xyz="-0.42 0 -0.42" rpy="0 0 0"/>
    <limit effort="100" lower="-0.4" upper="1.58" velocity="0.5"/>
  </joint>

  <link name="upper4">
  	<visual>
      <origin xyz="-0.212 0 -0.2" rpy="0 0.785 0"/>
      <geometry>
        <cylinder length="0.6" radius="0.1"/>
      </geometry>
      <material name="white"/>
    </visual>
    <collision>
      <geometry>
        <cylinder length="0.6" radius="0.1"/>
      </geometry>
    </collision>
    <inertial>
      <mass value="0.5"/>
      <inertia ixx="1.0" ixy="0.0" ixz="0.0" iyy="1.0" iyz="0.0" izz="1.0"/>
    </inertial>
  </link>

  <link name="lower4">
  	<visual>
      <origin xyz="0.147 0 -0.15" rpy="0 -0.785 0"/>
      <geometry>
        <cylinder length="0.6" radius="0.1"/>
      </geometry>
      <material name="blue"/>
    </visual>
    <collision>
      <geometry>
        <cylinder length="0.6" radius="0.1"/>
      </geometry>
    </collision>
    <inertial>
      <mass value="0.5"/>
      <inertia ixx="1.0" ixy="0.0" ixz="0.0" iyy="1.0" iyz="0.0" izz="1.0"/>
    </inertial>
  </link>

  <joint name="back_right_upper" type="revolute">
    <parent link="main_body"/>
    <child link="upper4"/> 
    <axis xyz="0 1 0"/>
    <origin xyz="-0.27 -0.25 0.6" rpy="0 0 0"/>
    <limit effort="100" lower="-1.6" upper="0.3" velocity="0.5"/>
  </joint> 

  <joint name="back_right_lower" type="revolute">
    <parent link="upper4"/>
    <child link="lower4"/>
    <axis xyz="0 1 0"/>
    <origin xyz="-0.42 0 -0.42" rpy="0 0 0"/>
    <limit effort="100" lower="-0.4" upper="1.58" velocity="0.5"/>
  </joint>
</robot>